<?xml version="1.0" encoding="UTF-8"?>
<testng-results skipped="1" failed="1" ignored="0" total="2" passed="0">
  <reporter-output>
  </reporter-output>
  <suite name="SeleniumOnlineProject3" duration-ms="11585" started-at="2021-01-10T20:27:33 BDT" finished-at="2021-01-10T20:27:45 BDT">
    <groups>
    </groups>
    <test name="LoginModule" duration-ms="11585" started-at="2021-01-10T20:27:33 BDT" finished-at="2021-01-10T20:27:45 BDT">
      <class name="com.bitm.SeleniumOnlineProject3.Test.LoginTest">
        <test-method status="FAIL" signature="homepagetitleverify()[pri:0, instance:com.bitm.SeleniumOnlineProject3.Test.LoginTest@77a57272]" name="homepagetitleverify" duration-ms="11103" started-at="2021-01-10T20:27:33 BDT" finished-at="2021-01-10T20:27:44 BDT">
          <exception class="java.lang.AssertionError">
            <message>
              <![CDATA[expected [OrangeHRMM] but found [OrangeHRM]]]>
            </message>
            <full-stacktrace>
              <![CDATA[java.lang.AssertionError: expected [OrangeHRMM] but found [OrangeHRM]
at org.testng.Assert.fail(Assert.java:99)
at org.testng.Assert.failNotEquals(Assert.java:1037)
at org.testng.Assert.assertEqualsImpl(Assert.java:140)
at org.testng.Assert.assertEquals(Assert.java:122)
at org.testng.Assert.assertEquals(Assert.java:629)
at org.testng.Assert.assertEquals(Assert.java:639)
at com.bitm.SeleniumOnlineProject3.Test.LoginTest.homepagetitleverify(LoginTest.java:27)
at sun.reflect.NativeMethodAccessorImpl.invoke0(Native Method)
at sun.reflect.NativeMethodAccessorImpl.invoke(NativeMethodAccessorImpl.java:62)
at sun.reflect.DelegatingMethodAccessorImpl.invoke(DelegatingMethodAccessorImpl.java:43)
at java.lang.reflect.Method.invoke(Method.java:497)
at org.testng.internal.MethodInvocationHelper.invokeMethod(MethodInvocationHelper.java:132)
at org.testng.internal.TestInvoker.invokeMethod(TestInvoker.java:599)
at org.testng.internal.TestInvoker.invokeTestMethod(TestInvoker.java:174)
at org.testng.internal.MethodRunner.runInSequence(MethodRunner.java:46)
at org.testng.internal.TestInvoker$MethodInvocationAgent.invoke(TestInvoker.java:822)
at org.testng.internal.TestInvoker.invokeTestMethods(TestInvoker.java:147)
at org.testng.internal.TestMethodWorker.invokeTestMethods(TestMethodWorker.java:146)
at org.testng.internal.TestMethodWorker.run(TestMethodWorker.java:128)
at org.testng.TestRunner$$Lambda$54/1800659519.accept(Unknown Source)
at java.util.ArrayList.forEach(ArrayList.java:1249)
at org.testng.TestRunner.privateRun(TestRunner.java:764)
at org.testng.TestRunner.run(TestRunner.java:585)
at org.testng.SuiteRunner.runTest(SuiteRunner.java:384)
at org.testng.SuiteRunner.runSequentially(SuiteRunner.java:378)
at org.testng.SuiteRunner.privateRun(SuiteRunner.java:337)
at org.testng.SuiteRunner.run(SuiteRunner.java:286)
at org.testng.SuiteRunnerWorker.runSuite(SuiteRunnerWorker.java:53)
at org.testng.SuiteRunnerWorker.run(SuiteRunnerWorker.java:96)
at org.testng.TestNG.runSuitesSequentially(TestNG.java:1218)
at org.testng.TestNG.runSuitesLocally(TestNG.java:1140)
at org.testng.TestNG.runSuites(TestNG.java:1069)
at org.testng.TestNG.run(TestNG.java:1037)
at org.testng.remote.AbstractRemoteTestNG.run(AbstractRemoteTestNG.java:115)
at org.testng.remote.RemoteTestNG.initAndRun(RemoteTestNG.java:251)
at org.testng.remote.RemoteTestNG.main(RemoteTestNG.java:77)
]]>
            </full-stacktrace>
          </exception> <!-- java.lang.AssertionError -->
          <reporter-output>
          </reporter-output>
        </test-method> <!-- homepagetitleverify -->
        <test-method status="SKIP" signature="logintest(java.util.List)[pri:0, instance:com.bitm.SeleniumOnlineProject3.Test.LoginTest@77a57272]" name="logintest" duration-ms="0" started-at="2021-01-10T20:27:45 BDT" data-provider="loginData" depends-on-methods="com.bitm.SeleniumOnlineProject3.Test.LoginTest.homepagetitleverify" finished-at="2021-01-10T20:27:45 BDT">
          <exception class="java.lang.Throwable">
            <message>
              <![CDATA[Method LoginTest.logintest(java.util.List)[pri:0, instance:com.bitm.SeleniumOnlineProject3.Test.LoginTest@77a57272] depends on not successfully finished methods]]>
            </message>
            <full-stacktrace>
              <![CDATA[java.lang.Throwable: Method LoginTest.logintest(java.util.List)[pri:0, instance:com.bitm.SeleniumOnlineProject3.Test.LoginTest@77a57272] depends on not successfully finished methods
at org.testng.internal.TestInvoker.invokeTestMethods(TestInvoker.java:102)
at org.testng.internal.TestMethodWorker.invokeTestMethods(TestMethodWorker.java:146)
at org.testng.internal.TestMethodWorker.run(TestMethodWorker.java:128)
at org.testng.TestRunner$$Lambda$54/1800659519.accept(Unknown Source)
at java.util.ArrayList.forEach(ArrayList.java:1249)
at org.testng.TestRunner.privateRun(TestRunner.java:764)
at org.testng.TestRunner.run(TestRunner.java:585)
at org.testng.SuiteRunner.runTest(SuiteRunner.java:384)
at org.testng.SuiteRunner.runSequentially(SuiteRunner.java:378)
at org.testng.SuiteRunner.privateRun(SuiteRunner.java:337)
at org.testng.SuiteRunner.run(SuiteRunner.java:286)
at org.testng.SuiteRunnerWorker.runSuite(SuiteRunnerWorker.java:53)
at org.testng.SuiteRunnerWorker.run(SuiteRunnerWorker.java:96)
at org.testng.TestNG.runSuitesSequentially(TestNG.java:1218)
at org.testng.TestNG.runSuitesLocally(TestNG.java:1140)
at org.testng.TestNG.runSuites(TestNG.java:1069)
at org.testng.TestNG.run(TestNG.java:1037)
at org.testng.remote.AbstractRemoteTestNG.run(AbstractRemoteTestNG.java:115)
at org.testng.remote.RemoteTestNG.initAndRun(RemoteTestNG.java:251)
at org.testng.remote.RemoteTestNG.main(RemoteTestNG.java:77)
]]>
            </full-stacktrace>
          </exception> <!-- java.lang.Throwable -->
          <reporter-output>
          </reporter-output>
        </test-method> <!-- logintest -->
      </class> <!-- com.bitm.SeleniumOnlineProject3.Test.LoginTest -->
    </test> <!-- LoginModule -->
  </suite> <!-- SeleniumOnlineProject3 -->
</testng-results>
